<?xml version="1.0"?>
<robot name="mbrb">
    <link name="chassis">
        <inertial>
            <origin xyz="0.0 0.0 45.0e-3" rpy="0.0 0.0 0.0"/>
            <mass value="1.0"/>
            <inertia ixx="1.0" ixy="0.0" ixz="0.0" iyy="1.0" iyz="0.0" izz="1.0"/>
        </inertial>
        <visual>
            <origin xyz="0.0 0.0 45.0e-3" rpy="0.0 0.0 0.0"/>
            <geometry>
                <mesh filename="package://rb_description/models/base.STL" scale="1 1 1"/>
            </geometry>
        </visual>
    </link>
    
    <joint name="left_wheel_joint" type="continuous">
        <origin xyz="0.04 0.07 0.0" rpy="-3.1416/2 0.0 0.0"/>
        <child>left_wheel</child>
        <parent>chassis</parent>
        <axis>
            <xyz>0 0 1</xyz>
        </axis>
    </joint>
    
    <link name="left_wheel">
        <inertial>
            <origin xyz="0.0 0.0 0.0" rpy="0.0 0.0 0.0"/>
            <mass value="1.0"/>
            <inertia ixx="1.0" ixy="0.0" ixz="0.0" iyy="1.0" iyz="0.0" izz="1.0"/>
        </inertial>
        <visual>
            <origin xyz="0.0 0.0 0" rpy="0.0 0.0 0.0"/>
            <geometry>
                <mesh filename="package://rb_description/models/wheel.STL" scale="1 1 1"/>
            </geometry>
        </visual>
    </link>

</robot>